Workbook
Name Slicer_Channel: #N/A

Sheet Notes & Assumptions
A1: Notes & Assumptions
A3: ABOUT THIS FILE
A4: • Tabs prefixed with a 1 use only Hershey's actual filings and part 2 use a synthetic dataset to demonstrate pricing mechanics. Part 2 therefore does not reconcile to Part 1's real numbers.
A6: SCOPE
A7: • This is a fully synthetic dataset built to represent an illustrative slice of Hershey's North America Confectionery segment - it is NOT disclosed data and does NOT reconcile to NA Confectionery's real FY2025 net sales ($9,479.7M per the 10-K). It's sized at a smaller, hand-checkable scale (~$170-180M annual net sales) on purpose, so unit volumes and formulas stay easy to sanity-check by hand.
A8: • 24 SKUs across 5 categories, 6 sales channels, 24 months (Jan 2024 - Dec 2025). 3,456 rows total.
A10: WHAT'S BUILT IN
A11: • Seasonality: confectionery sales peak around Halloween (Oct/Nov) and the winter holidays (Dec), with smaller lifts around Valentine's Day and Easter.
A12: • A cocoa-driven cost story: unit costs ramp up through 2025, consistent with the real cocoa price spike covered elsewhere in this workbook.
A13: • A price increase: list prices step up modestly in 2025, larger from July onward - consistent with the real price-realization story found in Hershey's own filings.
A14: • Two intentional analytical issues are planted somewhere in this data, the same way a real dataset would have real problems hiding in it. One involves discount behavior in a specific channel; the other involves a shift in product mix toward a lower-margin category. Both are found the same way you'd find them in real data - a discount trend by channel over time, and a category mix/margin breakdown - not listed here on purpose, so the pricing model built on top of this data has something real to catch.
A16: HOW TO USE THIS
... A19: • SKU Master and Channel Master are reference/lookup tables, not meant to be pivoted directly.

Sheet DashBoard
A1: Hershey NA Confectionery: FY2025
A2: KPI | B2: Where to click | C2: Value
A3: FY2025 Net Sales | B3: 1 - Annual Budget | C3: =SUM('1 - Annual Budget'!$B$2:$B$5) -> 11692.576
A4: FY2025 YoY Growth | B4: 1 - Annual Budget | C4: =('1 - Annual Budget'!B6/'1 - Annual Budget'!D6-1) -> 0.043769103
A5: Largest 2025 Growth Driver | B5: 1 - Annual Budget | C5: =SUM('1 - Annual Budget'!E2:E5) -> 348.08223
A6: H1 2026 Budget Cushion | B6: 1 - Annual Budget | C6: ='1 - Annual Budget'!D15+'1 - Annual Budget'!D16 -> 213.94525
A7: H2 2026 Break-Even Tolerance | B7: 1 - Annual Budget | C7: =('1 - Annual Budget'!D24-'1 - Annual Budget'!B24)/'1 - Annual Budget'!B24 -> -0.03256189
A8: Discount Leakage Found | B8: 2 - Diagnostics | C8: ='2 - Leakage Exploration'!G18-'2 - Leakage Exploration'!G16 -> 3573962.9
A9: Mix Shift Impact | B9: 2 - Diagnostics | C9: ='2 - Diagnostics'!B12-'2 - Diagnostics'!B15 -> -0.0039194272
A11: Label | B11: Source | C11: Cell
A12: FY2025 Net Sales | B12: 1 - Annual Segment PL | C12: ='1 - Annual Segment PL'!D10 -> 11692576
A13: FY2025 vs FY2024 | B13: (formula, not a link) components from 1 - Annual Budget | C13: =('1 - Annual Budget'!B37/'1 - Annual Budget'!B30)-1 -> 0.043769103
A14: H1 2026 Budget Cushion | B14: 2 - Annual Budget | C14: ='1 - Annual Budget'!B25 -> 213.94525
A15: FY2026 Forecast (Method A) | B15: 1 - Forecast | C15: ='1 - Forecast'!B39 -> 12709.509
A16: FY2026 Forecast (Guidance midpoint) | B16: 1 - Forecast | C16: =('1 - Forecast'!B43+'1 - Forecast'!B44)/2 -> 12247.973
A17: Discount Leakage Found | B17: 2 - Leakage Exploration | C17: ='2 - Leakage Exploration'!G20 -> 3573962.9
A36: Average of Discount % | B36: Column Labels
A37: Row Labels | B37: Club/Warehouse | C37: Convenience & Drug | D37: E-Commerce/DTC | E37: Grocery | F37: Mass Merchandiser | G37: Wholesale/Distributor | H37: Grand Total
A38: 2024-01 | B38: 0.1763625 | C38: 0.047433333 | D38: 0.071329167 | E38: 0.0993875 | F38: 0.13446667 | G38: 0.092895833 | H38: 0.10364583
A39: 2024-02 | B39: 0.18477917 | C39: 0.049429167 | D39: 0.070554167 | E39: 0.10487917 | F39: 0.13086667 | G39: 0.096679167 | H39: 0.10619792
A40: 2024-03 | B40: 0.18065 | C40: 0.051266667 | D40: 0.069779167 | E40: 0.096504167 | F40: 0.12802917 | G40: 0.091733333 | H40: 0.10299375
A41: 2024-04 | B41: 0.179825 | C41: 0.0472125 | D41: 0.0692 | E41: 0.099504167 | F41: 0.12212083 | G41: 0.093270833 | H41: 0.10185556
A42: 2024-05 | B42: 0.1780125 | C42: 0.051595833 | D42: 0.069954167 | E42: 0.0997875 | F42: 0.12787083 | G42: 0.095545833 | H42: 0.10379444
A43: 2024-06 | B43: 0.18164583 | C43: 0.051166667 | D43: 0.071529167 | E43: 0.096516667 | F43: 0.12942083 | G43: 0.085416667 | H43: 0.10261597
A44: 2024-07 | B44: 0.18129167 | C44: 0.050079167 | D44: 0.065779167 | E44: 0.099091667 | F44: 0.1243125 | G44: 0.0905625 | H44: 0.10185278
A45: 2024-08 | B45: 0.18072083 | C45: 0.049395833 | D45: 0.0693125 | E45: 0.097133333 | F45: 0.12797917 | G45: 0.092079167 | H45: 0.10277014
A46: 2024-09 | B46: 0.181025 | C46: 0.05195 | D46: 0.072716667 | E46: 0.0957375 | F46: 0.1305625 | G46: 0.089254167 | H46: 0.10354097
A47: 2024-10 | B47: 0.1793875 | C47: 0.046795833 | D47: 0.069141667 | E47: 0.0982375 | F47: 0.13329583 | G47: 0.08495 | H47: 0.10196806
A48: 2024-11 | B48: 0.180625 | C48: 0.0504375 | D48: 0.073108333 | E48: 0.098491667 | F48: 0.137575 | G48: 0.0915125 | H48: 0.10529167
A49: 2024-12 | B49: 0.18050417 | C49: 0.051866667 | D49: 0.0695875 | E49: 0.095345833 | F49: 0.12285833 | G49: 0.084516667 | H49: 0.10077986
... A62: Grand Total | B62: 0.18044323 | C62: 0.049902257 | D62: 0.070881944 | E62: 0.098802431 | F62: 0.12896094 | G62: 0.1386816 | H62: 0.11127873

Sheet 1 - Annual Segment PL
A1: The Hershey Company — Annual Segment P&L
A2: Source: FY2025 Form 10-K, Note re: Segment Information (filed 2026-02-17). See 'Sources & Notes' tab.
A4: $ in thousands
B5: FY2023 | C5: FY2024 | D5: FY2025
A6: Net Sales
A7: North America Confectionery | B7: 9123139 | C7: 9118590 | D7: 9479709
A8: North America Salty Snacks | B8: 1092689 | C8: 1135720 | D8: 1271299
A9: International | B9: 949164 | C9: 947953 | D9: 941568
A10: Total Net Sales | B10: =SUM(B7:B9) -> 11164992 | C10: =SUM(C7:C9) -> 11202263 | D10: =SUM(D7:D9) -> 11692576
A12: Net Sales Mix %
A13: North America Confectionery | B13: =B7/B10 -> 0.81712007 | C13: =C7/C10 -> 0.81399535 | D13: =D7/D10 -> 0.81074598
A14: North America Salty Snacks | B14: =B8/B10 -> 0.097867423 | C14: =C8/C10 -> 0.10138309 | D14: =D8/D10 -> 0.10872702
A15: International | B15: =B9/B10 -> 0.085012511 | C15: =C9/C10 -> 0.084621563 | D15: =D9/D10 -> 0.080526994
A17: Cost of Sales (segment-level)
A18: North America Confectionery | B18: 4781671 | C18: 4984764 | D18: 5796018
A19: North America Salty Snacks | B19: 726569 | C19: 719850 | D19: 804635
A20: International | B20: 601175 | C20: 642634 | D20: 740764
A21: Total Segment COGS | B21: =SUM(B18:B20) -> 6109415 | C21: =SUM(C18:C20) -> 6347248 | D21: =SUM(D18:D20) -> 7341417
A23: SM&A Expense (segment-level)
A24: North America Confectionery | B24: 1224424 | C24: 1188138 | D24: 1189959
A25: North America Salty Snacks | B25: 207787 | C25: 216480 | D25: 225311
A26: International | B26: 199730 | C26: 193800 | D26: 197486
A27: Total Segment SM&A | B27: =SUM(B24:B26) -> 1631941 | C27: =SUM(C24:C26) -> 1598418 | D27: =SUM(D24:D26) -> 1612756
A29: Segment Income — Calculated (Net Sales − COGS − SM&A)
A30: North America Confectionery | B30: =B7-B18-B24 -> 3117044 | C30: =C7-C18-C24 -> 2945688 | D30: =D7-D18-D24 -> 2493732
A31: North America Salty Snacks | B31: =B8-B19-B25 -> 158333 | C31: =C8-C19-C25 -> 199390 | D31: =D8-D19-D25 -> 241353
A32: International | B32: =B9-B20-B26 -> 148259 | C32: =C9-C20-C26 -> 111519 | D32: =D9-D20-D26 -> 3318
A33: Total Segment Income (calculated) | B33: =SUM(B30:B32) -> 3423636 | C33: =SUM(C30:C32) -> 3256597 | D33: =SUM(D30:D32) -> 2738403
A35: Segment Income — As Reported in 10-K (blue = filing input)
A36: North America Confectionery | B36: 3117044 | C36: 2945688 | D36: 2493732
A37: North America Salty Snacks | B37: 158333 | C37: 199390 | D37: 241353
A38: International | B38: 148259 | C38: 111519 | D38: 3318
A39: Total Segment Income (reported) | B39: 3423636 | C39: 3256597 | D39: 2738403
A40: Check: Calculated − Reported (should be 0) | B40: =B33-B39 -> 0 | C40: =C33-C39 -> 0 | D40: =D33-D39 -> 0
A42: Segment Margin % (reported segment income / net sales)
A43: North America Confectionery | B43: =B36/B7 -> 0.34166354 | C43: =C36/C7 -> 0.32304205 | D43: =D36/D7 -> 0.26305997
A44: North America Salty Snacks | B44: =B37/B8 -> 0.14490216 | C44: =C37/C8 -> 0.17556264 | D44: =D37/D8 -> 0.18984755
A45: International | B45: =B38/B9 -> 0.15619956 | C45: =C38/C9 -> 0.11764191 | D45: =D38/D9 -> 0.0035239091
A46: Total Segment Margin % | B46: =B39/B10 -> 0.30664026 | C46: =C39/C10 -> 0.29070885 | D46: =D39/D10 -> 0.23420015
A48: Reconciliation: Segment Income → Income Before Taxes
...

Sheet 1 - Quarterly Bridge
A1: The Hershey Company — Quarterly Consolidated Net Sales Bridge
A2: All figures are consolidated (company-wide), in $ millions unless noted. Point figures (%) are company-disclosed, rounded approximations — see Sources tab.
A4: Period | B4: Period End | C4: Net Sales ($M) | D4: % Chg — Reported | E4: FX Impact (pts) | F4: % Chg — Constant Currency (calc) | G4: Acquisition Impact (pts) | H4: % Chg — Organic CC | I4: Net Price Realization (pts) | J4: Volume/Mix (pts) | K4: Implied Volume/Mix (calc check) | L4: Notes | M4: Source
A5: Q1 2025 | B5: 3/30/2025 | C5: 2805.4 | D5: -13.8 | E5: -0.9 | F5: =D5-E5 -> -12.9 | G5: 0.3 | H5: -13.2 | I5: 2 | J5: -15 | K5: =IFERROR(IF(J5<>"",J5,H5-I5),"") -> -15 | L5: Lapped ERP-related inventory build & later Easter vs. 2024; Sour Strips acquisition. | M5: Q1'25 8-K Ex.99.1
A6: Q2 2025 | B6: 6/29/2025 | C6: 2614.7 | D6: 26 | E6: -0.7 | F6: =D6-E6 -> 26.7 | G6: 0.4 | H6: 26.3 | I6: 5 | J6: 21 | K6: =IFERROR(IF(J6<>"",J6,H6-I6),"") -> 21 | L6: Mirror-image lap of Q1: inventory timing & Easter shift reversed; Sour Strips acquisition. | M6: Q2'25 8-K Ex.99.1
A7: Q3 2025 | B7: 9/28/2025 | C7: 3181.4 | D7: 6.5 | E7: 0 | F7: =D7-E7 -> 6.5 | G7: 0.3 | H7: 6.2 | I7: 6 | J7: 0 | K7: =IFERROR(IF(J7<>"",J7,H7-I7),"") -> 0 | L7: Volume 'slightly positive.' FX impact immaterial. Gross margin fell to 32.6% (vs 41.3% Q3'24) on commodity/tariff costs. | M7: Q3'25 8-K Ex.99.1
A8: Q4 2025 | B8: 12/31/2025 | C8: =C9-SUM(C5:C7) -> 3091.076 | D8: 7 | E8: 0.1 | F8: 0 | G8: 1.2 | H8: 5.7 | I8: 0 | J8: 0 | K8: =IFERROR(IF(J8<>"",J8,H8-I8),"") -> 0 | L8: Net sales = FY total less 9-month YTD (derived). Consolidated price/volume pts not disclosed in narrative; NA Confectionery segment specifically: price +10 pts, volume/mix -5 pts (segment table). | M8: Q4'25 8-K Ex.99.1
A9: FY2025 Total | B9: 12/31/2025 | C9: 11692.576 | D9: 4.4 | E9: 0 | F9: 0 | G9: 0 | H9: 4.2 | I9: 0 | J9: 0 | K9: =IFERROR(IF(J9<>"",J9,H9-I9),"") -> 0 | L9: Full-year total, ties to Annual Segment PL tab. | M9: FY2025 10-K
A10: Q1 2026 | B10: 3/29/2026 | C10: 3104.2 | D10: 10.6 | E10: 0.7 | F10: =D10-E10 -> 9.9 | G10: 2 | H10: 7.9 | I10: 10 | J10: -2 | K10: =IFERROR(IF(J10<>"",J10,H10-I10),"") -> -2 | L10: LesserEvil acquisition (+2.0 pts). NA Confectionery segment: net sales $2,489.9M, price ~+12%, volume ~-4%. | M10: Q1'26 8-K Ex.99.1 / 10-Q
A11: Q2 2026 | B11: 6/28/2026 | C11: 2787.3 | D11: 6.6 | E11: 0.3 | F11: =D11-E11 -> 6.3 | G11: 2.7 | H11: 3.6 | I11: 12 | J11: -8 | K11: =IFERROR(IF(J11<>"",J11,H11-I11),"") -> -8 | L11: LesserEvil acquisition (+2.7 pts in release; ~3% cited in commentary). Volume elasticity to higher prices per company commentary. | M11: Q2'26 8-K Ex.99.1 / 10-Q
A13: Check: Q1+Q2+Q3+Q4 vs. FY2025 Total (should be ~0) | C13: =SUM(C5:C8)-C9 -> 0
A15: Reading this tab:
A16: • Blue cells = figures disclosed directly in a Hershey filing/press release. Black = calculated in this workbook.
A17: • 'Impact' and 'contribution' figures are Hershey's own non-GAAP, rounded approximations ('approximately X points'), not exact.
A18: • Constant-currency % = Reported % − FX impact; this reproduces the arithmetic Hershey uses in its own segment tables (see Sources tab).
A19: • 'Implied Volume/Mix' backs into volume/mix as a residual (Organic CC − Price) wherever Hershey didn't disclose it directly — same logic as the price/volume/mix bridge you'll build in the pricing model.
A20: • To extend this table: find the quarter's 8-K on SEC EDGAR, open the Exhibit 99.1 press release, and copy the 'Components of Net Sales Growth' table.

Sheet 1 - Annual Budget
B1: Net Sales ($M) | C1: % Chg - Reported | D1: 2024 Base | E1: Price ($M) | F1: Volume ($M) | G1: Acqusitions ($M) | H1: FX ($M) | I1: Organic (undecomposed $M) | J1: Explained ($M) | K1: Actual ($M) | L1: Residual ($M) | M1: % of FY2025
A2: Q1 2025 | B2: ='1 - Quarterly Bridge'!C5 -> 2805.4 | C2: ='1 - Quarterly Bridge'!D5/100 -> -0.138 | D2: =B2/(1+C2) -> 3254.5244 | E2: =D2*'1 - Quarterly Bridge'!I5/100 -> 65.090487 | F2: =D2*'1 - Quarterly Bridge'!J5/100 -> -488.17865 | G2: =D2*'1 - Quarterly Bridge'!G5/100 -> 9.7635731 | H2: =D2*'1 - Quarterly Bridge'!E5/100 -> -29.290719 | J2: =SUM(E2:I2) -> -442.61531 | K2: =B2-D2 -> -449.12436 | L2: =K2-J2 -> -6.5090487 | M2: =B2/$B$6 -> 0.23993002
A3: Q2 2025 | B3: ='1 - Quarterly Bridge'!C6 -> 2614.7 | C3: ='1 - Quarterly Bridge'!D6/100 -> 0.26 | D3: =B3/(1+C3) -> 2075.1587 | E3: =D3*'1 - Quarterly Bridge'!I6/100 -> 103.75794 | F3: =D3*'1 - Quarterly Bridge'!J6/100 -> 435.78333 | G3: =D3*'1 - Quarterly Bridge'!G6/100 -> 8.3006349 | H3: =D3*'1 - Quarterly Bridge'!E6/100 -> -14.526111 | J3: =SUM(E3:I3) -> 533.31579 | K3: =B3-D3 -> 539.54127 | L3: =K3-J3 -> 6.2254762 | M3: =B3/$B$6 -> 0.22362053
A4: Q3 2025 | B4: ='1 - Quarterly Bridge'!C7 -> 3181.4 | C4: ='1 - Quarterly Bridge'!D7/100 -> 0.065 | D4: =B4/(1+C4) -> 2987.23 | E4: =D4*'1 - Quarterly Bridge'!I7/100 -> 179.2338 | F4: 0 | G4: =D4*'1 - Quarterly Bridge'!G7/100 -> 8.9616901 | H4: 0 | J4: =SUM(E4:I4) -> 188.19549 | K4: =B4-D4 -> 194.16995 | L4: =K4-J4 -> 5.9744601 | M4: =B4/$B$6 -> 0.27208718
A5: Q4 2025 | B5: ='1 - Quarterly Bridge'!C8 -> 3091.076 | C5: ='1 - Quarterly Bridge'!D8/100 -> 0.07 | D5: =B5/(1+C5) -> 2888.8561 | G5: =D5*'1 - Quarterly Bridge'!G8/100 -> 34.666273 | H5: =D5*'1 - Quarterly Bridge'!E8/100 -> 2.8888561 | I5: =D5*'1 - Quarterly Bridge'!H8/100 -> 164.6648 | J5: =SUM(E5:I5) -> 202.21993 | K5: =B5-D5 -> 202.21993 | L5: =K5-J5 -> 0 | M5: =B5/$B$6 -> 0.26436228
A6: FY2025 | B6: =SUM($B$2:$B$5) -> 11692.576 | C6: =(B6/D6-1) -> 0.043769103 | D6: 11202.263 | E6: =SUM(E2:E5) -> 348.08223 | F6: =SUM(F2:F5) -> -52.395321 | G6: =SUM(G2:G5) -> 61.692171 | H6: =SUM(H2:H5) -> -40.927974 | I6: =SUM(I2:I5) -> 164.6648 | J6: =SUM(E6:I6) -> 481.1159 | K6: =B6-D6 -> 490.313 | L6: =K6-J6 -> 9.1971014 | M6: =B6/$B$6 -> 1
B9: Budgeted FY 2026 ($M)
A10: Low case 4.5% growth | B10: =B6*1.045 -> 12218.742
A11: Mid Point growth 4.75% | B11: =B6*1.0475 -> 12247.973
A12: High case 5% growth | B12: =B6*1.05 -> 12277.205
B14: Projected Net Sales ($M) | C14: Actual Net Sales ($M) | D14: $ Variance | E14: % Varince | F14: Current Estimate
A15: 2026 Q1 | B15: =$B$11*M2 -> 2938.6565 | C15: ='1 - Quarterly Bridge'!C10 -> 3104.2 | D15: =C15-B15 -> 165.5435 | E15: =D15/B15 -> 0.056333056 | F15: =IF(C15<>"", C15, B15) -> 3104.2
A16: 2026 Q2 | B16: =$B$11*M3 -> 2738.8982 | C16: ='1 - Quarterly Bridge'!C11 -> 2787.3 | D16: =C16-B16 -> 48.40175 | E16: =D16/B16 -> 0.017671978 | F16: =IF(C16<>"", C16, B16) -> 2787.3
A17: 2026 Q3 | B17: =$B$11*M4 -> 3332.5165 | F17: =IF(C17<>"", C17, B17) -> 3332.5165
A18: 2026 Q4 | B18: =$B$11*M5 -> 3237.9021 | F18: =IF(C18<>"", C18, B18) -> 3237.9021
A19: FY2026 Total | B19: =SUM(B15:B18) -> 12247.973 | D19: =F19-B19 -> 213.94525 | E19: =D19/B19 -> 0.017467808 | F19: =SUM(F15:F18) -> 12461.919
A24: H2 Budget | B24: =B17+B18 -> 6570.4186 | C24: Break-Even H2 | D24: =B24-B25 -> 6356.4734
A25: H1 Cushion | B25: =D15+D16 -> 213.94525 | C25: Break-Even % | D25: =(D24-B24)/B24 -> -0.03256189
A30: FY2024 Net Sales | B30: =D6 -> 11202.263
A31: Price | B31: =E6 -> 348.08223
A32: Volume | B32: =F6 -> -52.395321
A33: Acquisitions | B33: =G6 -> 61.692171
A34: FX | B34: =H6 -> -40.927974
A35: Organic (undecomposed) | B35: =I6 -> 164.6648
A36: Residual | B36: =L6 -> 9.1971014
A37: FY2025 Net Sales | B37: =B6 -> 11692.576

Sheet 1 - Cost-Driver
B1: Global Cocoa ($/metric ton) | C1: Ajdusted GM % | D1: Global Sugar (₵/lb) | E1: Hershey Gross Margin % | G1: Cocoa (Lagged 2Q)
A2: Q1 2024 | B2: 5793.5204 | C2: 0.449 | D2: 22.52858 | E2: 0.515 | G2: 3470.0693
A3: Q2 2024 | B3: 8671.1437 | C3: 0.432 | D3: 19.53878 | E3: 0.402 | G3: 4013.6251
A4: Q3 2024 | B4: 6792.8025 | C4: 0.403 | D4: 19.46535 | E4: 0.413 | G4: 5793.5204
A5: Q4 2024 | B5: 8304.7907 | C5: 0.448 | D5: 21.44076 | E5: 0.54 | G5: 8671.1437
A6: Q1 2025 | B6: 9527.5219 | C6: 0.412 | D6: 19.39056 | E6: 0.337 | G6: 6792.8025
A7: Q2 2025 | B7: 8511.6529 | C7: 0.381 | D7: 17.27646 | E7: 0.305 | G7: 8304.7907
A8: Q3 2025 | B8: 7327.5134 | C8: 0.318 | D8: 16.18144 | E8: 0.326 | G8: =B6 -> 9527.5219
A9: Q4 2025 | B9: 5786.3776 | C9: 0.383 | D9: 15.0389 | E9: 0.37 | G9: =B7 -> 8511.6529
A10: Q1 2026 | B10: 3948.9355 | C10: 0.404 | D10: 14.59459 | E10: 0.394 | G10: =B8 -> 7327.5134
A11: Q2 2026 | B11: 3976.8584 | C11: 0.416 | D11: 14.25607 | E11: 0.453 | G11: =B9 -> 5786.3776
A13: Cocoa Correlation Adjusted GM | B13: Cocoa Correlation Adjusted GM (Lagged Q2) | D13: Sugar Correlation Adjusted GM
A14: =CORREL(B2:B11,C2:C11) -> -0.0037938102 | B14: =CORREL(G2:G11,C2:C11) -> -0.65550334 | D14: =CORREL(D2:D11,C2:C11) -> 0.59094442
B19: FY2025 | C19: FY2024
A20: Reported Gross Profit | B20: 3922.7 | C20: 5300.9
A21: Derivative mark-to-market loss (gain) | B21: 423.2 | C21: -460.4
A22: Business Realignment activities | B22: 0 | C22: 12.2
A23: Acquistition/integration costs | B23: 5.3 | C23: 2.4
A24: Non-GAAP (Adjusted) gross profit | B24: 4351.2 | C24: 4855
A25: Reported Gross Margin % | B25: 0.335 | C25: 0.473
A26: Adjusted Gross Margin % | B26: 0.372 | C26: 0.433

Sheet 1 - Forecast
A3: H1 2025 | B3: ='1 - Quarterly Bridge'!C5+'1 - Quarterly Bridge'!C6 -> 5420.1
A4: H2 2025 | B4: ='1 - Quarterly Bridge'!C7+'1 - Quarterly Bridge'!C8 -> 6272.476
A5: H1 2026 | B5: ='1 - Quarterly Bridge'!C10+'1 - Quarterly Bridge'!C11 -> 5891.5
A6: H1 2024 (disclosed 6-month total) | B6: 5327.2
A7: FY2024 | B7: ='1 - Annual Segment PL'!C10/1000 -> 11202.263
A8: H2 2024 | B8: =B7-B6 -> 5875.063
A9: 9-month 2024 (disclosed) | B9: 8314.7
B13: =B5/B3-1 -> 0.086972565
B14: ='1 - Quarterly Bridge'!C7*(1+B13) -> 3458.0945
B15: ='1 - Quarterly Bridge'!C8*(1+B13) -> 3359.9148
B16: =B5+B14+B15 -> 12709.509
B19: =B8/B6 -> 1.1028426
B20: =B5*B19 -> 6497.3971
B21: =B5+B20 -> 12388.897
A26: Q3'24 | B26: =B9-B6 -> 2987.5
A27: Q4'24 | B27: =B7-B9 -> 2887.563
A28: Q1'25 | B28: ='1 - Quarterly Bridge'!C5 -> 2805.4
A29: Q2'25 | B29: ='1 - Quarterly Bridge'!C6 -> 2614.7 | C29: =SUM(B26:B29) -> 11295.163 | D29: 1
A30: Q3'25 | B30: ='1 - Quarterly Bridge'!C7 -> 3181.4 | C30: =SUM(B27:B30) -> 11489.063 | D30: 2
A31: Q4'25 | B31: ='1 - Quarterly Bridge'!C8 -> 3091.076 | C31: =SUM(B28:B31) -> 11692.576 | D31: 3
A32: Q1'26 | B32: ='1 - Quarterly Bridge'!C10 -> 3104.2 | C32: =SUM(B29:B32) -> 11991.376 | D32: 4
A33: Q2'26 | B33: ='1 - Quarterly Bridge'!C11 -> 2787.3 | C33: =SUM(B30:B33) -> 12163.976 | D33: 5
A34: Q3'26 (forecast) | B34: =B30+(C34-C33) -> 3415.8365 | C34: =_xlfn.FORECAST.LINEAR(D34,$C$29:$C$33,$D$29:$D$33) -> 12398.412 | D34: 6
A35: Q4'26 (forecast) | B35: =B31+(C35-C34) -> 3315.0699 | C35: =_xlfn.FORECAST.LINEAR(D35,$C$29:$C$33,$D$29:$D$33) -> 12622.406 | D35: 7
B37: =B3+B4 -> 11692.576
B38: FY2026 | C38: vs. FY2025 | D38: Implied H2 Growth
A39: Method A | B39: =B16 -> 12709.509 | C39: =B39/$B$37-1 -> 0.086972565 | D39: =(B39-$B$5)/$B$4-1 -> 0.086972565
A40: Method B | B40: =B21 -> 12388.897 | C40: =B40/$B$37-1 -> 0.059552409 | D40: =(B40-$B$5)/$B$4-1 -> 0.035858418
A41: Method C | B41: =C35 -> 12622.406 | C41: =B41/$B$37-1 -> 0.079523144 | D41: =(B41-$B$5)/$B$4-1 -> 0.073086035
A42: Budget-based Current Estimate | B42: 12446.2 | C42: =B42/$B$37-1 -> 0.064453205 | D42: =(B42-$B$5)/$B$4-1 -> 0.044994034
A43: Guidance low | B43: =$B$37*(1+C43) -> 12218.742 | C43: 0.045 | D43: =(B43-$B$5)/$B$4-1 -> 0.0087311486
A44: Guidance high | B44: =$B$37*(1+C44) -> 12277.205 | C44: 0.05 | D44: =(B44-$B$5)/$B$4-1 -> 0.018051691

Sheet 2 - Raw Data
A1: SKU_ID | B1: SKU | C1: Category | D1: Channel | E1: Month | F1: Units | G1: List Price | H1: Discount % | I1: Unit Cost | J1: Net Price | K1: Revenue | L1: COGS | M1: Gross Profit | N1: Gross Margin % | O1: Counterfactual Net Price | P1: Counterfactual Revenue
A2: SKU-01 | B2: Classic Milk Bar 1.5oz | C2: Standard Bar | D2: Grocery | E2: 2024-01 | F2: 121538 | G2: 1.29 | H2: 0.0844 | I2: 0.7482 | J2: =G2*(1-H2) -> 1.181124 | K2: =F2*J2 -> 143551.45 | L2: =F2*I2 -> 90934.732 | M2: =K2-L2 -> 52616.717 | N2: =IFERROR(M2/K2,"") -> 0.36653561 | O2: =IF(AND(RawData[[#This Row],[Channel]]="Wholesale/Distributor", LEFT(RawData[[#This Row],[Month]], 4)="2025"),RawData[[#This Row],[List Price]]*(1-'2 - Diagnostics'!$B$1),RawData[[#This Row],[Net Price]]) -> 1.181124 | P2: =RawData[[#This Row],[Units]]*RawData[[#This Row],[Counterfactual Net Price]] -> 143551.45
A3: SKU-01 | B3: Classic Milk Bar 1.5oz | C3: Standard Bar | D3: Grocery | E3: 2024-02 | F3: 154722 | G3: 1.29 | H3: 0.1141 | I3: 0.7482 | J3: =G3*(1-H3) -> 1.142811 | K3: =F3*J3 -> 176818 | L3: =F3*I3 -> 115763 | M3: =K3-L3 -> 61055.003 | N3: =IFERROR(M3/K3,"") -> 0.34529857 | O3: =IF(AND(RawData[[#This Row],[Channel]]="Wholesale/Distributor", LEFT(RawData[[#This Row],[Month]], 4)="2025"),RawData[[#This Row],[List Price]]*(1-'2 - Diagnostics'!$B$1),RawData[[#This Row],[Net Price]]) -> 1.142811 | P3: =RawData[[#This Row],[Units]]*RawData[[#This Row],[Counterfactual Net Price]] -> 176818
A4: SKU-01 | B4: Classic Milk Bar 1.5oz | C4: Standard Bar | D4: Grocery | E4: 2024-03 | F4: 126924 | G4: 1.29 | H4: 0.0805 | I4: 0.7482 | J4: =G4*(1-H4) -> 1.186155 | K4: =F4*J4 -> 150551.54 | L4: =F4*I4 -> 94964.537 | M4: =K4-L4 -> 55587 | N4: =IFERROR(M4/K4,"") -> 0.3692224 | O4: =IF(AND(RawData[[#This Row],[Channel]]="Wholesale/Distributor", LEFT(RawData[[#This Row],[Month]], 4)="2025"),RawData[[#This Row],[List Price]]*(1-'2 - Diagnostics'!$B$1),RawData[[#This Row],[Net Price]]) -> 1.186155 | P4: =RawData[[#This Row],[Units]]*RawData[[#This Row],[Counterfactual Net Price]] -> 150551.54
A5: SKU-01 | B5: Classic Milk Bar 1.5oz | C5: Standard Bar | D5: Grocery | E5: 2024-04 | F5: 155378 | G5: 1.29 | H5: 0.0953 | I5: 0.7482 | J5: =G5*(1-H5) -> 1.167063 | K5: =F5*J5 -> 181335.91 | L5: =F5*I5 -> 116253.82 | M5: =K5-L5 -> 65082.095 | N5: =IFERROR(M5/K5,"") -> 0.3589035 | O5: =IF(AND(RawData[[#This Row],[Channel]]="Wholesale/Distributor", LEFT(RawData[[#This Row],[Month]], 4)="2025"),RawData[[#This Row],[List Price]]*(1-'2 - Diagnostics'!$B$1),RawData[[#This Row],[Net Price]]) -> 1.167063 | P5: =RawData[[#This Row],[Units]]*RawData[[#This Row],[Counterfactual Net Price]] -> 181335.91
A6: SKU-01 | B6: Classic Milk Bar 1.5oz | C6: Standard Bar | D6: Grocery | E6: 2024-05 | F6: 125852 | G6: 1.29 | H6: 0.0872 | I6: 0.7482 | J6: =G6*(1-H6) -> 1.177512 | K6: =F6*J6 -> 148192.24 | L6: =F6*I6 -> 94162.466 | M6: =K6-L6 -> 54029.774 | N6: =IFERROR(M6/K6,"") -> 0.36459246 | O6: =IF(AND(RawData[[#This Row],[Channel]]="Wholesale/Distributor", LEFT(RawData[[#This Row],[Month]], 4)="2025"),RawData[[#This Row],[List Price]]*(1-'2 - Diagnostics'!$B$1),RawData[[#This Row],[Net Price]]) -> 1.177512 | P6: =RawData[[#This Row],[Units]]*RawData[[#This Row],[Counterfactual Net Price]] -> 148192.24
A7: SKU-01 | B7: Classic Milk Bar 1.5oz | C7: Standard Bar | D7: Grocery | E7: 2024-06 | F7: 126325 | G7: 1.29 | H7: 0.1117 | I7: 0.7482 | J7: =G7*(1-H7) -> 1.145907 | K7: =F7*J7 -> 144756.7 | L7: =F7*I7 -> 94516.365 | M7: =K7-L7 -> 50240.337 | N7: =IFERROR(M7/K7,"") -> 0.34706743 | O7: =IF(AND(RawData[[#This Row],[Channel]]="Wholesale/Distributor", LEFT(RawData[[#This Row],[Month]], 4)="2025"),RawData[[#This Row],[List Price]]*(1-'2 - Diagnostics'!$B$1),RawData[[#This Row],[Net Price]]) -> 1.145907 | P7: =RawData[[#This Row],[Units]]*RawData[[#This Row],[Counterfactual Net Price]] -> 144756.7
A8: SKU-01 | B8: Classic Milk Bar 1.5oz | C8: Standard Bar | D8: Grocery | E8: 2024-07 | F8: 112518 | G8: 1.29 | H8: 0.1169 | I8: 0.7482 | J8: =G8*(1-H8) -> 1.139199 | K8: =F8*J8 -> 128180.39 | L8: =F8*I8 -> 84185.968 | M8: =K8-L8 -> 43994.425 | N8: =IFERROR(M8/K8,"") -> 0.34322274 | O8: =IF(AND(RawData[[#This Row],[Channel]]="Wholesale/Distributor", LEFT(RawData[[#This Row],[Month]], 4)="2025"),RawData[[#This Row],[List Price]]*(1-'2 - Diagnostics'!$B$1),RawData[[#This Row],[Net Price]]) -> 1.139199 | P8: =RawData[[#This Row],[Units]]*RawData[[#This Row],[Counterfactual Net Price]] -> 128180.39
A9: SKU-01 | B9: Classic Milk Bar 1.5oz | C9: Standard Bar | D9: Grocery | E9: 2024-08 | F9: 130123 | G9: 1.29 | H9: 0.0871 | I9: 0.7482 | J9: =G9*(1-H9) -> 1.177641 | K9: =F9*J9 -> 153238.18 | L9: =F9*I9 -> 97358.029 | M9: =K9-L9 -> 55880.151 | N9: =IFERROR(M9/K9,"") -> 0.36466207 | O9: =IF(AND(RawData[[#This Row],[Channel]]="Wholesale/Distributor", LEFT(RawData[[#This Row],[Month]], 4)="2025"),RawData[[#This Row],[List Price]]*(1-'2 - Diagnostics'!$B$1),RawData[[#This Row],[Net Price]]) -> 1.177641 | P9: =RawData[[#This Row],[Units]]*RawData[[#This Row],[Counterfactual Net Price]] -> 153238.18
A10: SKU-01 | B10: Classic Milk Bar 1.5oz | C10: Standard Bar | D10: Grocery | E10: 2024-09 | F10: 150794 | G10: 1.29 | H10: 0.0856 | I10: 0.7482 | J10: =G10*(1-H10) -> 1.179576 | K10: =F10*J10 -> 177872.98 | L10: =F10*I10 -> 112824.07 | M10: =K10-L10 -> 65048.913 | N10: =IFERROR(M10/K10,"") -> 0.36570429 | O10: =IF(AND(RawData[[#This Row],[Channel]]="Wholesale/Distributor", LEFT(RawData[[#This Row],[Month]], 4)="2025"),RawData[[#This Row],[List Price]]*(1-'2 - Diagnostics'!$B$1),RawData[[#This Row],[Net Price]]) -> 1.179576 | P10: =RawData[[#This Row],[Units]]*RawData[[#This Row],[Counterfactual Net Price]] -> 177872.98
A11: SKU-01 | B11: Classic Milk Bar 1.5oz | C11: Standard Bar | D11: Grocery | E11: 2024-10 | F11: 230344 | G11: 1.29 | H11: 0.0993 | I11: 0.7482 | J11: =G11*(1-H11) -> 1.161903 | K11: =F11*J11 -> 267637.38 | L11: =F11*I11 -> 172343.38 | M11: =K11-L11 -> 95294.004 | N11: =IFERROR(M11/K11,"") -> 0.3560564 | O11: =IF(AND(RawData[[#This Row],[Channel]]="Wholesale/Distributor", LEFT(RawData[[#This Row],[Month]], 4)="2025"),RawData[[#This Row],[List Price]]*(1-'2 - Diagnostics'!$B$1),RawData[[#This Row],[Net Price]]) -> 1.161903 | P11: =RawData[[#This Row],[Units]]*RawData[[#This Row],[Counterfactual Net Price]] -> 267637.38
A12: SKU-01 | B12: Classic Milk Bar 1.5oz | C12: Standard Bar | D12: Grocery | E12: 2024-11 | F12: 228011 | G12: 1.29 | H12: 0.0898 | I12: 0.7482 | J12: =G12*(1-H12) -> 1.174158 | K12: =F12*J12 -> 267720.94 | L12: =F12*I12 -> 170597.83 | M12: =K12-L12 -> 97123.11 | N12: =IFERROR(M12/K12,"") -> 0.36277741 | O12: =IF(AND(RawData[[#This Row],[Channel]]="Wholesale/Distributor", LEFT(RawData[[#This Row],[Month]], 4)="2025"),RawData[[#This Row],[List Price]]*(1-'2 - Diagnostics'!$B$1),RawData[[#This Row],[Net Price]]) -> 1.174158 | P12: =RawData[[#This Row],[Units]]*RawData[[#This Row],[Counterfactual Net Price]] -> 267720.94
A13: SKU-01 | B13: Classic Milk Bar 1.5oz | C13: Standard Bar | D13: Grocery | E13: 2024-12 | F13: 205174 | G13: 1.29 | H13: 0.0977 | I13: 0.7482 | J13: =G13*(1-H13) -> 1.163967 | K13: =F13*J13 -> 238815.77 | L13: =F13*I13 -> 153511.19 | M13: =K13-L13 -> 85304.578 | N13: =IFERROR(M13/K13,"") -> 0.35719827 | O13: =IF(AND(RawData[[#This Row],[Channel]]="Wholesale/Distributor", LEFT(RawData[[#This Row],[Month]], 4)="2025"),RawData[[#This Row],[List Price]]*(1-'2 - Diagnostics'!$B$1),RawData[[#This Row],[Net Price]]) -> 1.163967 | P13: =RawData[[#This Row],[Units]]*RawData[[#This Row],[Counterfactual Net Price]] -> 238815.77
... A3457: SKU-24 | B3457: Trick-or-Treat Variety Bag | C3457: Seasonal Assortment | D3457: E-Commerce/DTC | E3457: 2025-12 | F3457: 12559 | G3457: 11.54 | H3457: 0.0611 | I3457: 6.2291 | J3457: =G3457*(1-H3457) -> 10.834906 | K3457: =F3457*J3457 -> 136075.58 | L3457: =F3457*I3457 -> 78231.267 | M3457: =K3457-L3457 -> 57844.318 | N3457: =IFERROR(M3457/K3457,"") -> 0.42508961 | O3457: =IF(AND(RawData[[#This Row],[Channel]]="Wholesale/Distributor", LEFT(RawData[[#This Row],[Month]], 4)="2025"),RawData[[#This Row],[List Price]]*(1-'2 - Diagnostics'!$B$1),RawData[[#This Row],[Net Price]]) -> 10.834906 | P3457: =RawData[[#This Row],[Units]]*RawData[[#This Row],[Counterfactual Net Price]] -> 136075.58

Sheet 2 - Channel Master
A1: Channel Master
A2: Reference list of the 6 sales channels with their baseline (2024) discount range.
A4: Channel | B4: Base Discount % | C4: Discount Noise (SD) | D4: Relative Volume Weight
A5: Grocery | B5: 0.1 | C5: 0.015 | D5: 1
A6: Mass Merchandiser | B6: 0.13 | C6: 0.015 | D6: 0.85
A7: Club/Warehouse | B7: 0.18 | C7: 0.015 | D7: 0.55
A8: Convenience & Drug | B8: 0.05 | C8: 0.01 | D8: 0.45
A9: Wholesale/Distributor | B9: 0.09 | C9: 0.015 | D9: 0.65
A10: E-Commerce/DTC | B10: 0.07 | C10: 0.015 | D10: 0.3

Sheet 2 - SKU Master
A1: SKU Master
A2: Reference list of all 24 SKUs with their baseline (2024) list price and cost ratio.
A4: SKU_ID | B4: SKU | C4: Category | D4: Base List Price (2024) | E4: Base Cost Ratio | F4: Base Volume Weight
A5: SKU-01 | B5: Classic Milk Bar 1.5oz | C5: Standard Bar | D5: 1.29 | E5: 0.58 | F5: 140
A6: SKU-02 | B6: Classic Milk Bar Sharing Size | C6: Standard Bar | D6: 2.49 | E6: 0.57 | F6: 60
A7: SKU-03 | B7: Dark Chocolate Bar 1.5oz | C7: Standard Bar | D7: 1.39 | E7: 0.59 | F7: 90
A8: SKU-04 | B8: Almond Milk Bar 1.5oz | C8: Standard Bar | D8: 1.49 | E8: 0.58 | F8: 70
A9: SKU-05 | B9: Cookies n Cream Bar | C9: Standard Bar | D9: 1.39 | E9: 0.57 | F9: 80
A10: SKU-06 | B10: Mini Bars Multipack | C10: Standard Bar | D10: 3.49 | E10: 0.56 | F10: 55
A11: SKU-07 | B11: PB Cup 2-Pack | C11: Peanut Butter Cup | D11: 1.49 | E11: 0.55 | F11: 150
A12: SKU-08 | B12: PB Cup King 4-Pack | C12: Peanut Butter Cup | D12: 2.29 | E12: 0.56 | F12: 65
A13: SKU-09 | B13: PB Cup Minis Bag | C13: Peanut Butter Cup | D13: 3.99 | E13: 0.54 | F13: 45
A14: SKU-10 | B14: Dark PB Cup 2-Pack | C14: Peanut Butter Cup | D14: 1.59 | E14: 0.56 | F14: 55
A15: SKU-11 | B15: PB Cup Big Bag | C15: Peanut Butter Cup | D15: 6.49 | E15: 0.55 | F15: 25
A16: SKU-12 | B16: Crisp Wafer Bar | C16: Wafer/Crisp | D16: 1.39 | E16: 0.56 | F16: 100
... A28: SKU-24 | B28: Trick-or-Treat Variety Bag | C28: Seasonal Assortment | D28: 10.99 | E28: 0.52 | F28: 30

Sheet 2 - Diagnostics
A1: Baseline Discount, Wholesale/Distributor | B1: 0.09
A3: category | B3: 2024 Units | C3: 2024 Share | D3: 2025 Units(Actual) | E3: 2025 Revenue (Actual) | F3: 2025 COGS (actual) | G3: 2025 Avg Net Price | H3: 2025 Avg Unit Cost | I3: Hypothetical Units | J3: Hypothetical Revenue | K3: Hypothetical COGS
A4: Standard Bar | B4: =SUMIFS(RawData[Units],RawData[Category],A4,RawData[Month],"2024-*") -> 24530017 | C4: =B4/SUM($B$4:$B$8) -> 0.35347524 | D4: =SUMIFS(RawData[Units],RawData[Category],A4,RawData[Month],"2025-*") -> 22939721 | E4: =SUMIFS(RawData[Revenue],RawData[Category],A4,RawData[Month],"2025-*") -> 36278590 | F4: =SUMIFS(RawData[COGS],RawData[Category],A4,RawData[Month],"2025-*") -> 24179159 | G4: =E4/D4 -> 1.5814748 | H4: =F4/D4 -> 1.0540302 | I4: =C4*SUM($D$4:$D$8) -> 24665813 | J4: =I4*G4 -> 39008361 | K4: =I4*H4 -> 25998511
A5: Peanut Butter Cup | B5: =SUMIFS(RawData[Units],RawData[Category],A5,RawData[Month],"2024-*") -> 16736988 | C5: =B5/SUM($B$4:$B$8) -> 0.24117842 | D5: =SUMIFS(RawData[Units],RawData[Category],A5,RawData[Month],"2025-*") -> 16691019 | E5: =SUMIFS(RawData[Revenue],RawData[Category],A5,RawData[Month],"2025-*") -> 35700456 | F5: =SUMIFS(RawData[COGS],RawData[Category],A5,RawData[Month],"2025-*") -> 22893935 | G5: =E5/D5 -> 2.1389021 | H5: =F5/D5 -> 1.371632 | I5: =C5*SUM($D$4:$D$8) -> 16829642 | J5: =I5*G5 -> 35996957 | K5: =I5*H5 -> 23084075
A6: Wafer/Crisp | B6: =SUMIFS(RawData[Units],RawData[Category],A6,RawData[Month],"2024-*") -> 13187182 | C6: =B6/SUM($B$4:$B$8) -> 0.19002605 | D6: =SUMIFS(RawData[Units],RawData[Category],A6,RawData[Month],"2025-*") -> 13037608 | E6: =SUMIFS(RawData[Revenue],RawData[Category],A6,RawData[Month],"2025-*") -> 22185418 | F6: =SUMIFS(RawData[COGS],RawData[Category],A6,RawData[Month],"2025-*") -> 14551503 | G6: =E6/D6 -> 1.7016479 | H6: =F6/D6 -> 1.1161175 | I6: =C6*SUM($D$4:$D$8) -> 13260185 | J6: =I6*G6 -> 22564165 | K6: =I6*H6 -> 14799925
A7: King Size | B7: =SUMIFS(RawData[Units],RawData[Category],A7,RawData[Month],"2024-*") -> 10196510 | C7: =B7/SUM($B$4:$B$8) -> 0.14693075 | D7: =SUMIFS(RawData[Units],RawData[Category],A7,RawData[Month],"2025-*") -> 12404205 | E7: =SUMIFS(RawData[Revenue],RawData[Category],A7,RawData[Month],"2025-*") -> 35912689 | F7: =SUMIFS(RawData[COGS],RawData[Category],A7,RawData[Month],"2025-*") -> 27535278 | G7: =E7/D7 -> 2.8952028 | H7: =F7/D7 -> 2.2198342 | I7: =C7*SUM($D$4:$D$8) -> 10252957 | J7: =I7*G7 -> 29684389 | K7: =I7*H7 -> 22759864
A8: Seasonal Assortment | B8: =SUMIFS(RawData[Units],RawData[Category],A8,RawData[Month],"2024-*") -> 4746009 | C8: =B8/SUM($B$4:$B$8) -> 0.068389543 | D8: =SUMIFS(RawData[Units],RawData[Category],A8,RawData[Month],"2025-*") -> 4708326 | E8: =SUMIFS(RawData[Revenue],RawData[Category],A8,RawData[Month],"2025-*") -> 43773014 | F8: =SUMIFS(RawData[COGS],RawData[Category],A8,RawData[Month],"2025-*") -> 26582035 | G8: =E8/D8 -> 9.2969379 | H8: =F8/D8 -> 5.6457508 | I8: =C8*SUM($D$4:$D$8) -> 4772282.4 | J8: =I8*G8 -> 44367613 | K8: =I8*H8 -> 26943117
A10: Actual Revenue Total | B10: =SUM(E4:E8) -> 1.7385017e+08
A11: Actual COGS Total | B11: =SUM(F2:F8) -> 1.1574191e+08
A12: Actual Margin % | B12: =(B10 - B11)/B10 -> 0.33424332
A13: Hypothetical Revenue Total | B13: =SUM(J4:J8) -> 1.7162149e+08
A14: Hypothetical COGS Total | B14: =SUM(K4:K8) -> 1.1358549e+08
A15: Hypothetical Margin% | B15: =(B13-B14)/B13 -> 0.33816275
A16: Mix Effect (points) | B16: =B12-B15 -> -0.0039194272
A18: SKU-ID | B18: SKU | C18: Revenue | D18: COGS | E18: Margin %
A19: SKU-21 | B19: =_xlfn.XLOOKUP(A19, '2 - Raw Data'!A:A, '2 - Raw Data'!B:B) -> Holiday Gift Box Large | C19: =SUMIFS(RawData[Revenue], RawData[SKU_ID], A19, RawData[Month], "2025-*") -> 8055557.5 | D19: =SUMIFS(RawData[COGS],RawData[SKU_ID],A19,RawData[Month],"2025-*") -> 4779282.1 | E19: =(C19-D19)/C19 -> 0.40670996
A20: SKU-20 | B20: =_xlfn.XLOOKUP(A20, '2 - Raw Data'!A:A, '2 - Raw Data'!B:B) -> Holiday Gift Box Small | C20: =SUMIFS(RawData[Revenue], RawData[SKU_ID], A20, RawData[Month], "2025-*") -> 8109114.7 | D20: =SUMIFS(RawData[COGS],RawData[SKU_ID],A20,RawData[Month],"2025-*") -> 4894040 | E20: =(C20-D20)/C20 -> 0.39647666
A21: SKU-24 | B21: =_xlfn.XLOOKUP(A21, '2 - Raw Data'!A:A, '2 - Raw Data'!B:B) -> Trick-or-Treat Variety Bag | C21: =SUMIFS(RawData[Revenue], RawData[SKU_ID], A21, RawData[Month], "2025-*") -> 14576353 | D21: =SUMIFS(RawData[COGS],RawData[SKU_ID],A21,RawData[Month],"2025-*") -> 8828307.5 | E21: =(C21-D21)/C21 -> 0.39434045
A22: SKU-22 | B22: =_xlfn.XLOOKUP(A22, '2 - Raw Data'!A:A, '2 - Raw Data'!B:B) -> Valentine Heart Box | C22: =SUMIFS(RawData[Revenue], RawData[SKU_ID], A22, RawData[Month], "2025-*") -> 6565963.3 | D22: =SUMIFS(RawData[COGS],RawData[SKU_ID],A22,RawData[Month],"2025-*") -> 4027954.3 | E22: =(C22-D22)/C22 -> 0.38654024
A23: SKU-23 | B23: =_xlfn.XLOOKUP(A23, '2 - Raw Data'!A:A, '2 - Raw Data'!B:B) -> Easter Assortment Bag | C23: =SUMIFS(RawData[Revenue], RawData[SKU_ID], A23, RawData[Month], "2025-*") -> 6466025.6 | D23: =SUMIFS(RawData[COGS],RawData[SKU_ID],A23,RawData[Month],"2025-*") -> 4052451.5 | E23: =(C23-D23)/C23 -> 0.37327011
A24: SKU-09 | B24: =_xlfn.XLOOKUP(A24, '2 - Raw Data'!A:A, '2 - Raw Data'!B:B) -> PB Cup Minis Bag | C24: =SUMIFS(RawData[Revenue], RawData[SKU_ID], A24, RawData[Month], "2025-*") -> 8034754.9 | D24: =SUMIFS(RawData[COGS],RawData[SKU_ID],A24,RawData[Month],"2025-*") -> 5057690.6 | E24: =(C24-D24)/C24 -> 0.37052334
A25: SKU-14 | B25: =_xlfn.XLOOKUP(A25, '2 - Raw Data'!A:A, '2 - Raw Data'!B:B) -> Wafer Minis Bag | C25: =SUMIFS(RawData[Revenue], RawData[SKU_ID], A25, RawData[Month], "2025-*") -> 5934697.7 | D25: =SUMIFS(RawData[COGS],RawData[SKU_ID],A25,RawData[Month],"2025-*") -> 3791298.3 | E25: =(C25-D25)/C25 -> 0.36116405
A26: SKU-11 | B26: =_xlfn.XLOOKUP(A26, '2 - Raw Data'!A:A, '2 - Raw Data'!B:B) -> PB Cup Big Bag | C26: =SUMIFS(RawData[Revenue], RawData[SKU_ID], A26, RawData[Month], "2025-*") -> 7293227.7 | D26: =SUMIFS(RawData[COGS],RawData[SKU_ID],A26,RawData[Month],"2025-*") -> 4665414.3 | E26: =(C26-D26)/C26 -> 0.3603087
A27: SKU-07 | B27: =_xlfn.XLOOKUP(A27, '2 - Raw Data'!A:A, '2 - Raw Data'!B:B) -> PB Cup 2-Pack | C27: =SUMIFS(RawData[Revenue], RawData[SKU_ID], A27, RawData[Month], "2025-*") -> 9833974.3 | D27: =SUMIFS(RawData[COGS],RawData[SKU_ID],A27,RawData[Month],"2025-*") -> 6310504.6 | E27: =(C27-D27)/C27 -> 0.3582956
A28: SKU-06 | B28: =_xlfn.XLOOKUP(A28, '2 - Raw Data'!A:A, '2 - Raw Data'!B:B) -> Mini Bars Multipack | C28: =SUMIFS(RawData[Revenue], RawData[SKU_ID], A28, RawData[Month], "2025-*") -> 8128058.7 | D28: =SUMIFS(RawData[COGS],RawData[SKU_ID],A28,RawData[Month],"2025-*") -> 5264998.4 | E28: =(C28-D28)/C28 -> 0.35224404
A29: SKU-08 | B29: =_xlfn.XLOOKUP(A29, '2 - Raw Data'!A:A, '2 - Raw Data'!B:B) -> PB Cup King 4-Pack | C29: =SUMIFS(RawData[Revenue], RawData[SKU_ID], A29, RawData[Month], "2025-*") -> 6661669.4 | D29: =SUMIFS(RawData[COGS],RawData[SKU_ID],A29,RawData[Month],"2025-*") -> 4332012.6 | E29: =(C29-D29)/C29 -> 0.34971066
A30: SKU-12 | B30: =_xlfn.XLOOKUP(A30, '2 - Raw Data'!A:A, '2 - Raw Data'!B:B) -> Crisp Wafer Bar | C30: =SUMIFS(RawData[Revenue], RawData[SKU_ID], A30, RawData[Month], "2025-*") -> 6190718.3 | D30: =SUMIFS(RawData[COGS],RawData[SKU_ID],A30,RawData[Month],"2025-*") -> 4028992.3 | E30: =(C30-D30)/C30 -> 0.34918825
... A42: SKU-17 | B42: =_xlfn.XLOOKUP(A42, '2 - Raw Data'!A:A, '2 - Raw Data'!B:B) -> King Size PB Cup 6-Pack | C42: =SUMIFS(RawData[Revenue], RawData[SKU_ID], A42, RawData[Month], "2025-*") -> 11509900 | D42: =SUMIFS(RawData[COGS],RawData[SKU_ID],A42,RawData[Month],"2025-*") -> 8913992.3 | E42: =(C42-D42)/C42 -> 0.22553698

Sheet 2 - Leakage Exploration
A1: Average of Discount % | B1: Column Labels
B2: Group2 | C2: Grand Total
A3: Row Labels
A4: Wholesale/Distributor | B4: 0.18666181 | C4: 0.18666181
A5: Grand Total | B5: 0.18666181 | C5: 0.18666181
A6: Channel | B6: Change in discount, Jan→Dec 2025
A7: Wholesale/Distributor | B7: 16.1
A8: Convenience & Drug | B8: 0.3
A9: Mass Merchandiser | B9: 0.1
A10: Club/Warehouse | B10: -0.3
A11: E-Commerce/DTC | B11: -0.3
A12: Grocery | B12: -0.5
B15: Column Labels | G15: Actual Revenue
B16: Wholesale/Distributor | D16: Total Average of Discount % | E16: Total Sum of Units | G16: =SUMIFS(RawData[Revenue], RawData[Channel], "Wholesale/Distributor",RawData[Month], "2025-*") -> 27364066
A17: Row Labels | B17: Average of Discount % | C17: Sum of Units | G17: Counterfactual Revenue
A18: 2024 | B18: 0.090701389 | C18: 11841463 | D18: 0.090701389 | E18: 11841463 | G18: =SUMIFS(RawData[Counterfactual Revenue], RawData[Channel], "Wholesale/Distributor",RawData[Month], "2025-*") -> 30938029
A19: 2025 | B19: 0.18666181 | C19: 11872283 | D19: 0.18666181 | E19: 11872283 | G19: Foregone Revenue
A20: Grand Total | B20: 0.1386816 | C20: 23713746 | D20: 0.1386816 | E20: 23713746 | G20: =G18-G16 -> 3573962.9
G21: % of Channels Actual Revenue
G22: =G20/G16 -> 0.13060789
G23: % of Total Company Revenue
G24: =G20/SUMIFS(RawData[Revenue], RawData[Month], "2025-*") -> 0.020557719

Sheet 2 - Cascade
A1: Units | B1: =SUMIFS(RawData[Units],RawData[Category],"King Size",RawData[Month],"2025-*") -> 12404205
A2: Gross Revenue (at list price) | B2: {=SUMPRODUCT((RawData[Category]="King Size")*(LEFT(RawData[Month],4)="2025")*RawData[Units]*RawData[List Price])} -> 40988852
A3: Discount $ | B3: =-(B2-B4) -> -5076163.4
A4: Net Revenue (actual) | B4: =SUMIFS(RawData[Revenue],RawData[Category],"King Size",RawData[Month],"2025-*") -> 35912689
A5: COGS | B5: =-SUMIFS(RawData[COGS],RawData[Category],"King Size",RawData[Month],"2025-*") -> -27535278
A6: Gross Profit | B6: =B4+B5 -> 8377410.6
B9: =B6/B4 -> 0.23327161

Sheet 2 - Goal Seek
A4: Price change % | B4: 0.095323875
A5: Price elasticity | B5: -1.2
F6: Change in Gross Profit ($), price change across, elasticity down
A7: Metric | B7: Baseline | C7: Scenario | D7: Change | F7: =D13 -> 2073465.1 | G7: 0.02 | H7: 0.05 | I7: 0.08 | J7: 0.1
A8: Units | B8: =SUMIFS(RawData[Units],RawData[Category],"King Size",RawData[Month],"2025-*") -> 12404205 | C8: =B8*(1+$B$5*$B$4) -> 10985305 | D8: =C8-B8 -> -1418900.3 | F8: -0.5 | G8: 627297.13 | H8: 1541308.3 | I8: 2422998.1 | J8: 2992834.9
A9: Avg Net Price | B9: =B11/B8 -> 2.8952028 | C9: =B9*(1+$B$4) -> 3.1711847 | D9: =C9-B9 -> 0.27598195 | F9: -1 | G9: 536340.49 | H9: 1286982.2 | I9: 1972981 | J9: 2394400.9
A10: Avg Unit Cost | B10: =B12/B8 -> 2.2198342 | C10: =B10 -> 2.2198342 | F10: -1.2 | G10: 499957.83 | H10: 1185251.7 | I10: 1792974.2 | J10: 2155027.3
A11: Net Revenue | B11: =SUMIFS(RawData[Revenue],RawData[Category],"King Size",RawData[Month],"2025-*") -> 35912689 | C11: =C8*C9 -> 34836430 | D11: =C11-B11 -> -1076258.2 | F11: -2 | G11: 354427.2 | H11: 778329.93 | I11: 1072947 | J11: 1197533
A12: COGS | B12: =SUMIFS(RawData[COGS],RawData[Category],"King Size",RawData[Month],"2025-*") -> 27535278 | C12: =C8*C10 -> 24385555 | D12: =C12-B12 -> -3149723.3 | F12: -3 | G12: 172513.91 | H12: 269677.68 | I12: 172912.92 | J12: 665.02293
A13: Gross Profit | B13: =B11-B12 -> 8377410.6 | C13: =C11-C12 -> 10450876 | D13: =C13-B13 -> 2073465.1 | F13: -4 | G13: -9399.3775 | H13: -238974.58 | I13: -727121.13 | J13: -1196202.9
A14: Margin % | B14: =B13/B11 -> 0.23327161 | C14: =C13/C11 -> 0.29999847 | D14: =C14-B14 -> 0.066726858

Sheet Sources
A1: Sources & Notes
A2: Every figure in this workbook traces back to one of the filings below. CIK for The Hershey Company: 0000047111.
A4: Data used for | B4: Source document | C4: Filing date | D4: URL
A5: Annual segment P&L, FY2023-FY2025 (net sales, COGS, SM&A, segment income, D&A, geography) | B5: Hershey FY2025 Form 10-K, Note re: Segment Information | C5: 2026-02-17 | D5: https://www.sec.gov/Archives/edgar/data/47111/000162828026008586/R22.htm
A6: Q1 2025 net sales & headline growth | B6: Hershey Q1 2025 earnings release, Ex. 99.1 to 8-K | C6: 2025-05-01 | D6: https://www.sec.gov/Archives/edgar/data/47111/000004711125000040/exhibit991_2025xq1.htm
A7: Q1 2025 price/volume detail (~2 pt price, ~15 pt volume decline) | B7: As quoted from Hershey's Q1 2025 earnings release | C7: 2025-05-01 | D7: https://ccentral.ca/hershey-reports-first-quarter-results-2025
A8: Q2 2025 net sales, growth, and price/volume detail | B8: Hershey Q2 2025 earnings release, Ex. 99.1 to 8-K | C8: 2025-07-30 | D8: https://seekingalpha.com/pr/20182273-hershey-reports-second-quarter-2025-financial-results
A9: Q3 2025 net sales, growth, price/volume detail, gross margin | B9: Hershey Q3 2025 earnings release, Ex. 99.1 to 8-K | C9: 2025-10-30 | D9: https://www.sec.gov/Archives/edgar/data/47111/000162828025047294/exhibit991_2025xq3.htm
A10: Q3 2025 nine-month net sales bridge (cross-check) | B10: Hershey Q3 2025 Form 10-Q, MD&A | C10: 2025-10-30 | D10: https://www.sec.gov/Archives/edgar/data/47111/000162828025047471/hsy-20250928.htm
A11: Q4 2025 / FY2025 net sales, growth, segment detail | B11: Hershey Q4 & FY2025 earnings release, Ex. 99.1 to 8-K | C11: 2026-02-17 | D11: https://www.sec.gov/Archives/edgar/data/47111/000162828026005604/exhibit991-q42025.htm
A12: Q4 2025 headline figures (secondary summary, cross-check) | B12: Milling & Baking News article summarizing Q4/FY2025 release | C12: 2026-02 | D12: https://www.bakingbusiness.com/articles/65634-hershey-profits-dampened-by-input-costs
A13: Q1 2026 net sales, growth, price/volume detail, NA Confectionery segment detail | B13: Hershey Q1 2026 earnings release, Ex. 99.1 to 8-K | C13: 2026-04-30 | D13: https://www.sec.gov/Archives/edgar/data/0000047111/000162828026028682/hsy-20260329.htm
A14: Q2 2026 net sales, growth, price/volume detail | B14: Hershey Q2 2026 Form 10-Q, MD&A | C14: 2026-07-30 | D14: https://www.sec.gov/Archives/edgar/data/0000047111/000162828026050900/hsy-20260628.htm
A15: Q2 2026 headline figures (cross-check) | B15: Hershey Q2 2026 earnings release, Ex. 99.1 to 8-K | C15: 2026-07-30 | D15: https://www.sec.gov/Archives/edgar/data/0000047111/000162828026050769/exhibit991_2026xq2.htm
A16: Reportable segment definitions | B16: Zacks Equity Research report on HSY | C16: 2025-12-16 | D16: https://advisortools.zacks.com/proxy/ResearchReport/HSY/report?d=20251216
A18: Important caveats & scoping notes
A19: • No SKU-level, customer-level, or unit price/volume/cost data is disclosed anywhere in Hershey's public filings. The SKU-level pricing/elasticity/Goal Seek layer uses a separate synthetic dataset.
A20: • All quarterly price and volume/mix percentages are Hershey's own disclosed, rounded, non-GAAP approximations ("approximately X points") — not derived from underlying unit data. Treat them as directionally accurate, not exact to a tenth of a point.
A21: • Hershey's fiscal quarters are ~13-week periods ending on a Sunday near month-end, not calendar quarters. See the exact period-end dates in the Quarterly Bridge tab.
A22: • To pull additional quarters or segment-level quarterly detail: SEC EDGAR full-text search → Hershey → 8-K filings → open the Exhibit 99.1 press release for the desired quarter → 'Components of Net Sales Growth' table.
